Workbook

Sheet Material Details
A1: DATE | B1: CATEGORY | C1: COMPANY | D1: DEALER | E1: QTY | F1: MEASURING IN | G1: RATE | H1: TOTAL BILL AMOUNT | I1: Column1
A2: 45918 | B2: M-SAND | D2: RSK | E2: 4 | F2: =IFERROR(VLOOKUP(B2,'Reference Table'!$A$2:$C$20,2,FALSE),"") -> UNITS | G2: 5125 | H2: =E2*G2 -> 20500
A3: 45918 | B3: 40 MM METAL | D3: RSK | E3: 4 | F3: =IFERROR(VLOOKUP(B3,'Reference Table'!$A$2:$C$20,2,FALSE),"") -> UNITS | G3: 4450 | H3: =E3*G3 -> 17800
A4: 45918 | B4: STEEL | C4: VIZAG | D4: AK STEELS | E4: 1445 | F4: =IFERROR(VLOOKUP(B4,'Reference Table'!$A$2:$C$20,2,FALSE),"") -> KG | H4: 90780
A5: 45919 | B5: CEMENT | C5: JSW | D5: PALANI MURUGAN | E5: 60 | F5: =IFERROR(VLOOKUP(B5,'Reference Table'!$A$2:$C$20,2,FALSE),"") -> BAGS | G5: 320 | H5: =E5*G5 -> 19200
A6: 45921 | B6: STEEL | C6: VIZAG | D6: AK STEELS | F6: =IFERROR(VLOOKUP(B6,'Reference Table'!$A$2:$C$20,2,FALSE),"") -> KG | H6: 80650
A7: 45922 | B7: M-SAND | D7: RSK | E7: 4 | F7: =IFERROR(VLOOKUP(B7,'Reference Table'!$A$2:$C$20,2,FALSE),"") -> UNITS | G7: 5125 | H7: =E7*G7 -> 20500
A8: 45922 | B8: 20 MM JALLY | D8: RSK | E8: 4 | F8: =IFERROR(VLOOKUP(B8,'Reference Table'!$A$2:$C$20,2,FALSE),"") -> UNITS | G8: 4450 | H8: =E8*G8 -> 17800
A9: 45923 | B9: CEMENT | C9: JSW | D9: PALANI MURUGAN | E9: 60 | F9: =IFERROR(VLOOKUP(B9,'Reference Table'!$A$2:$C$20,2,FALSE),"") -> BAGS | G9: 300 | H9: =E9*G9 -> 18000
A10: 45924 | B10: BRICK | C10: VEL | D10: VEL BRICK | E10: 12000 | F10: =IFERROR(VLOOKUP(B10,'Reference Table'!$A$2:$C$20,2,FALSE),"") -> NOS | G10: 11.4 | H10: =E10*G10 -> 136800
A11: 45924 | B11: P-SAND | D11: RSK | E11: 4 | F11: =IFERROR(VLOOKUP(B11,'Reference Table'!$A$2:$C$20,2,FALSE),"") -> UNITS | G11: 5750 | H11: =E11*G11 -> 23000
A12: 45925 | B12: GRAVEL | D12: RSK | E12: 4 | F12: =IFERROR(VLOOKUP(B12,'Reference Table'!$A$2:$C$20,2,FALSE),"") -> UNITS | G12: 2250 | H12: =E12*G12 -> 9000
A13: 45934 | B13: 20 MM JALLY | D13: RSK | E13: 4 | F13: =IFERROR(VLOOKUP(B13,'Reference Table'!$A$2:$C$20,2,FALSE),"") -> UNITS | G13: 4450 | H13: =E13*G13 -> 17800
A14: 45934 | B14: M-SAND | D14: RSK | E14: 4 | F14: =IFERROR(VLOOKUP(B14,'Reference Table'!$A$2:$C$20,2,FALSE),"") -> UNITS | G14: 5125 | H14: =E14*G14 -> 20500
A15: 45935 | B15: CEMENT | C15: JSW | D15: PALANI MURUGAN | E15: 100 | F15: =IFERROR(VLOOKUP(B15,'Reference Table'!$A$2:$C$20,2,FALSE),"") -> BAGS | G15: 295 | H15: =E15*G15 -> 29500
A16: 45940 | B16: GRAVEL | D16: RSK | E16: 20 | F16: =IFERROR(VLOOKUP(B16,'Reference Table'!$A$2:$C$20,2,FALSE),"") -> UNITS | G16: 2250 | H16: =Table1[[#This Row],[QTY]]*Table1[[#This Row],[RATE]] -> 45000
A17: 45941 | B17: CEMENT | C17: JSW | D17: PALANI MURUGAN | E17: 60 | F17: =IFERROR(VLOOKUP(B17,'Reference Table'!$A$2:$C$20,2,FALSE),"") -> BAGS | G17: 295 | H17: =Table1[[#This Row],[QTY]]*Table1[[#This Row],[RATE]] -> 17700
A18: 45944 | B18: M-SAND | D18: RSK | E18: 4 | F18: =IFERROR(VLOOKUP(B18,'Reference Table'!$A$2:$C$20,2,FALSE),"") -> UNITS | G18: 5125 | H18: =Table1[[#This Row],[QTY]]*Table1[[#This Row],[RATE]] -> 20500
A19: 45945 | B19: 20 MM JALLY | D19: RSK | E19: 4 | F19: =IFERROR(VLOOKUP(B19,'Reference Table'!$A$2:$C$20,2,FALSE),"") -> UNITS | G19: 4450 | H19: =Table1[[#This Row],[QTY]]*Table1[[#This Row],[RATE]] -> 17800
A20: 45943 | B20: STEEL | C20: VIZAG | D20: AK STEELS | E20: 115 | F20: =IFERROR(VLOOKUP(B20,'Reference Table'!$A$2:$C$20,2,FALSE),"") -> KG | H20: 8350
A21: 45954 | B21: BRICK | C21: VEL | D21: VEL BRICK | E21: 12000 | F21: =IFERROR(VLOOKUP(B21,'Reference Table'!$A$2:$C$20,2,FALSE),"") -> NOS | G21: 11.4 | H21: =Table1[[#This Row],[QTY]]*Table1[[#This Row],[RATE]] -> 136800
A22: 45958 | B22: CEMENT | C22: JSW | D22: PALANI MURUGAN | E22: 60 | F22: =IFERROR(VLOOKUP(B22,'Reference Table'!$A$2:$C$20,2,FALSE),"") -> BAGS | G22: 295 | H22: =Table1[[#This Row],[QTY]]*Table1[[#This Row],[RATE]] -> 17700
A23: 45960 | B23: STEEL | C23: VIZAG | D23: AK STEELS | E23: 290 | F23: =IFERROR(VLOOKUP(B23,'Reference Table'!$A$2:$C$20,2,FALSE),"") -> KG | H23: 19490
A24: 45978 | B24: STEEL | C24: VIZAG | D24: AK STEELS | E24: 1762 | F24: =IFERROR(VLOOKUP(B24,'Reference Table'!$A$2:$C$20,2,FALSE),"") -> KG | H24: 110410
A25: 45983 | B25: ELECTRICAL | C25: KAVERY | D25: RAMDEV ELECTRICALS | H25: 6941
A26: 45985 | B26: M-SAND | D26: RSK | E26: 4 | F26: =IFERROR(VLOOKUP(B26,'Reference Table'!$A$2:$C$20,2,FALSE),"") -> UNITS | G26: 5125 | H26: =Table1[[#This Row],[QTY]]*Table1[[#This Row],[RATE]] -> 20500
A27: 45985 | B27: 20 MM JALLY | D27: RSK | E27: 4 | F27: =IFERROR(VLOOKUP(B27,'Reference Table'!$A$2:$C$20,2,FALSE),"") -> UNITS | G27: 4450 | H27: =Table1[[#This Row],[QTY]]*Table1[[#This Row],[RATE]] -> 17800
A28: 45985 | B28: CEMENT | C28: JSW | D28: PALANI MURUGAN | E28: 120 | F28: =IFERROR(VLOOKUP(B28,'Reference Table'!$A$2:$C$20,2,FALSE),"") -> BAGS | G28: 280 | H28: =Table1[[#This Row],[QTY]]*Table1[[#This Row],[RATE]] -> 33600
A29: 46002 | B29: STEEL | C29: VIZAG | D29: AK STEELS | E29: 583 | F29: =IFERROR(VLOOKUP(B29,'Reference Table'!$A$2:$C$20,2,FALSE),"") -> KG | H29: 38090
A30: 46009 | B30: M-SAND | D30: RSK | E30: 4 | F30: =IFERROR(VLOOKUP(B30,'Reference Table'!$A$2:$C$20,2,FALSE),"") -> UNITS | G30: 5125 | H30: =Table1[[#This Row],[QTY]]*Table1[[#This Row],[RATE]] -> 20500
A31: 46010 | B31: CEMENT | C31: JSW | D31: PALANI MURUGAN | E31: 50 | F31: =IFERROR(VLOOKUP(B31,'Reference Table'!$A$2:$C$20,2,FALSE),"") -> BAGS | G31: 280 | H31: =Table1[[#This Row],[QTY]]*Table1[[#This Row],[RATE]] -> 14000
A32: 46015 | B32: BRICK | C32: VEL | D32: VEL BRICK | E32: 5000 | F32: =IFERROR(VLOOKUP(B32,'Reference Table'!$A$2:$C$20,2,FALSE),"") -> NOS | G32: 12 | H32: =Table1[[#This Row],[QTY]]*Table1[[#This Row],[RATE]] -> 60000
A33: 46016 | B33: ELECTRICAL | D33: RAMDEV ELECTRICALS | F33: =IFERROR(VLOOKUP(B33,'Reference Table'!$A$2:$C$20,2,FALSE),"") -> 0 | H33: 15335
A34: 46019 | B34: OTHERS | D34: RAMDEV ELECTRICALS | F34: =IFERROR(VLOOKUP(B34,'Reference Table'!$A$2:$C$20,2,FALSE),"") -> 0 | H34: 1310
A35: 46024 | B35: CEMENT | C35: JSW | D35: PALANI MURUGAN | E35: 60 | F35: =IFERROR(VLOOKUP(B35,'Reference Table'!$A$2:$C$20,2,FALSE),"") -> BAGS | G35: 270 | H35: =Table1[[#This Row],[QTY]]*Table1[[#This Row],[RATE]] -> 16200
A36: 46044 | B36: STEEL | C36: VIZAG | D36: AK STEELS | E36: 1874 | F36: =IFERROR(VLOOKUP(B36,'Reference Table'!$A$2:$C$20,2,FALSE),"") -> KG | G36: 70.94 | H36: =Table1[[#This Row],[QTY]]*Table1[[#This Row],[RATE]] -> 132941.56
A37: 46050 | B37: ELECTRICAL | D37: RAMDEV ELECTRICALS | F37: =IFERROR(VLOOKUP(B37,'Reference Table'!$A$2:$C$20,2,FALSE),"") -> 0 | H37: 5885 | I37: roof FF
A38: 46050 | B38: M-SAND | D38: RSK | E38: 4 | F38: =IFERROR(VLOOKUP(B38,'Reference Table'!$A$2:$C$20,2,FALSE),"") -> UNITS | G38: 5125 | H38: =Table1[[#This Row],[QTY]]*Table1[[#This Row],[RATE]] -> 20500
A39: 46050 | B39: 20 MM JALLY | D39: RSK | E39: 4 | F39: =IFERROR(VLOOKUP(B39,'Reference Table'!$A$2:$C$20,2,FALSE),"") -> UNITS | G39: 4450 | H39: =Table1[[#This Row],[QTY]]*Table1[[#This Row],[RATE]] -> 17800
A40: 46050 | B40: CEMENT | C40: JSW | D40: NV ASSOCIATES | E40: 100 | F40: =IFERROR(VLOOKUP(B40,'Reference Table'!$A$2:$C$20,2,FALSE),"") -> BAGS | G40: 275 | H40: =Table1[[#This Row],[QTY]]*Table1[[#This Row],[RATE]] -> 27500
...

Sheet Reference Table
A1: CATEGORY | B1: MEASURING IN | C1: RATE
A2: M-SAND | B2: UNITS | C2: 5125
A3: 40 MM METAL | B3: UNITS | C3: 4450
A4: BRICK | B4: NOS | C4: 7.2
A5: 20 MM JALLY | B5: UNITS | C5: 4450
A6: P-SAND | B6: UNITS | C6: 5950
A7: GRAVEL | B7: UNITS | C7: 2200
A8: CEMENT | B8: BAGS
A9: STEEL | B9: KG
A10: ELECTRICAL
A11: OTHERS
A12: BABY CHIPS | B12: UNITS
A13: BRICK-FLYASH | B13: NOS
A14: PAINTING
A15: PLUMBING
A16: TILES
A17: TILES PASTE

Sheet Materials Total QTY
A1: MATERIALS | B1: QTY | C1: MEASURING IN | D1: TOTAL AMOUNT
A2: {=_xlfn.UNIQUE('Material Details'!B2:B1009)} -> M-SAND | B2: =SUMIF('Material Details'!B2:B1009,A2,'Material Details'!E2:E1009) -> 38 | C2: UNITS | D2: =SUMIF('Material Details'!B2:B1009,A2,'Material Details'!H2:H1009) -> 194750
A3: 40 MM METAL | B3: =SUMIF('Material Details'!B3:B1010,A3,'Material Details'!E3:E1010) -> 4 | C3: UNITS | D3: =SUMIF('Material Details'!B3:B1010,A3,'Material Details'!H3:H1010) -> 17800
A4: STEEL | B4: =SUMIF('Material Details'!B4:B1011,A4,'Material Details'!E4:E1011) -> 7075 | C4: KG | D4: =SUMIF('Material Details'!B4:B1011,A4,'Material Details'!H4:H1011) -> 565821.32
A5: CEMENT | B5: =SUMIF('Material Details'!B5:B1012,A5,'Material Details'!E5:E1012) -> 1085 | C5: BAGS | D5: =SUMIF('Material Details'!B5:B1012,A5,'Material Details'!H5:H1012) -> 314675
A6: 20 MM JALLY | B6: =SUMIF('Material Details'!B6:B1013,A6,'Material Details'!E6:E1013) -> 24 | C6: NOS | D6: =SUMIF('Material Details'!B6:B1013,A6,'Material Details'!H6:H1013) -> 108000
A7: BRICK | B7: =SUMIF('Material Details'!B7:B1014,A7,'Material Details'!E7:E1014) -> 33600 | C7: UNITS | D7: =SUMIF('Material Details'!B7:B1014,A7,'Material Details'!H7:H1014) -> 388800
A8: P-SAND | B8: =SUMIF('Material Details'!B9:B1015,A8,'Material Details'!E9:E1015) -> 12 | C8: UNITS | D8: =SUMIF('Material Details'!B8:B1015,A8,'Material Details'!H8:H1015) -> 69000
A9: GRAVEL | B9: =SUMIF('Material Details'!B10:B1016,A9,'Material Details'!E10:E1016) -> 24 | C9: UNITS | D9: =SUMIF('Material Details'!B9:B1016,A9,'Material Details'!H9:H1016) -> 54000
A10: ELECTRICAL | B10: =SUMIF('Material Details'!B11:B1017,A10,'Material Details'!E11:E1017) -> 0 | C10: UNITS | D10: =SUMIF('Material Details'!B10:B1017,A10,'Material Details'!H10:H1017) -> 40271
A11: OTHERS | B11: =SUMIF('Material Details'!B12:B1018,A11,'Material Details'!E12:E1018) -> 0 | C11: UNITS | D11: =SUMIF('Material Details'!B11:B1018,A11,'Material Details'!H11:H1018) -> 1310
A12: BABY CHIPS | B12: =SUMIF('Material Details'!B13:B1019,A12,'Material Details'!E13:E1019) -> 2 | C12: UNITS | D12: =SUMIF('Material Details'!B12:B1019,A12,'Material Details'!H12:H1019) -> 9500
A13: BRICK-FLYASH | B13: =SUMIF('Material Details'!B14:B1020,A13,'Material Details'!E14:E1020) -> 3000 | C13: UNITS | D13: =SUMIF('Material Details'!B13:B1020,A13,'Material Details'!H13:H1020) -> 24900
A14: PAINTING | B14: =SUMIF('Material Details'!B15:B1021,A14,'Material Details'!E15:E1021) -> 0 | C14: UNITS | D14: =SUMIF('Material Details'!B14:B1021,A14,'Material Details'!H14:H1021) -> 13230
A15: PLUMBING | B15: =SUMIF('Material Details'!B16:B1022,A15,'Material Details'!E16:E1022) -> 0 | C15: UNITS | D15: =SUMIF('Material Details'!B15:B1022,A15,'Material Details'!H15:H1022) -> 55983
A16: TILES | B16: =SUMIF('Material Details'!B17:B1023,A16,'Material Details'!E17:E1023) -> 0 | C16: UNITS | D16: =SUMIF('Material Details'!B16:B1023,A16,'Material Details'!H16:H1023) -> 230845
A17: TILES PASTE
A18: 0

Sheet Vendor Balance Sheet
A1: VENDOR NAME | B1: TOTAL BILL AMOUNT | C1: TOTAL AMOUNT PAID | D1: BALANCE AMOUNT
A2: {=_xlfn.UNIQUE('Material Details'!D2:D1009)} -> RSK | B2: =SUMIF('Material Details'!D2:D1009,A2,'Material Details'!H2:H1009) -> 453050 | C2: =SUMIF('Payment Details'!B2:B992,'Vendor Balance Sheet'!A2,'Payment Details'!C2:C992) -> 450000 | D2: =B2-C2 -> 3050
A3: AK STEELS | B3: =SUMIF('Material Details'!D2:D1009,A3,'Material Details'!H2:H1009) -> 565821.32 | C3: =SUMIF('Payment Details'!B2:B993,'Vendor Balance Sheet'!A3,'Payment Details'!C2:C993) -> 527150 | D3: =B3-C3 -> 38671.32
A4: PALANI MURUGAN | B4: =SUMIF('Material Details'!D3:D1010,A4,'Material Details'!H3:H1010) -> 224025 | C4: =SUMIF('Payment Details'!B2:B992,'Vendor Balance Sheet'!A4,'Payment Details'!C2:C992) -> 224025 | D4: =B4-C4 -> 0
A5: VEL BRICK | B5: =SUMIF('Material Details'!D4:D1011,A5,'Material Details'!H4:H1011) -> 388800 | C5: =SUMIF('Payment Details'!B2:B993,'Vendor Balance Sheet'!A5,'Payment Details'!C2:C993) -> 388800 | D5: =B5-C5 -> 0
A6: RAMDEV ELECTRICALS | B6: =SUMIF('Material Details'!D5:D1012,A6,'Material Details'!H5:H1012) -> 109794 | C6: =SUMIF('Payment Details'!B3:B994,'Vendor Balance Sheet'!A6,'Payment Details'!C3:C994) -> 103550 | D6: =B6-C6 -> 6244
A7: NV ASSOCIATES | B7: =SUMIF('Material Details'!D6:D1013,A7,'Material Details'!H6:H1013) -> 41250 | C7: =SUMIF('Payment Details'!B4:B995,'Vendor Balance Sheet'!A7,'Payment Details'!C4:C995) -> 41250 | D7: =B7-C7 -> 0
A8: CHAKRA TRADERS | B8: =SUMIF('Material Details'!D7:D1014,A8,'Material Details'!H7:H1014) -> 49400 | C8: =SUMIF('Payment Details'!B5:B996,'Vendor Balance Sheet'!A8,'Payment Details'!C5:C996) -> 43500 | D8: =B8-C8 -> 5900
A9: 0 | C9: =SUMIF('Payment Details'!B6:B997,'Vendor Balance Sheet'!A9,'Payment Details'!C6:C997) -> 0 | D9: =B9-C9 -> 0
A10: AMARUN FLYASH | B10: =SUMIF('Material Details'!D9:D1016,A10,'Material Details'!H9:H1016) -> 24900 | C10: =SUMIF('Payment Details'!B7:B998,'Vendor Balance Sheet'!A10,'Payment Details'!C7:C998) -> 24900 | D10: =B10-C10 -> 0
A11: LAKSHMI CERAMICS | B11: =SUMIF('Material Details'!D10:D1017,A11,'Material Details'!H10:H1017) -> 230845 | C11: =SUMIF('Payment Details'!B8:B999,'Vendor Balance Sheet'!A11,'Payment Details'!C8:C999) -> 230845 | D11: =B11-C11 -> 0
A12: ICONIC TRADERS | B12: =SUMIF('Material Details'!D11:D1018,A12,'Material Details'!H11:H1018) -> 11600 | C12: =SUMIF('Payment Details'!B9:B1000,'Vendor Balance Sheet'!A12,'Payment Details'!C9:C1000) -> 11600 | D12: =B12-C12 -> 0

Sheet Payment Details
A1: DATE | B1: VENDOR NAME | C1: AMOUNT PAID | D1: MODE OF PAYMENT | E1: GST BILL | F1: DESCRPTION
A2: 45919 | B2: AK STEELS | C2: 90780 | D2: CASH | E2: YES | F2: Footing Steel
A3: 45925 | B3: VEL BRICK | C3: 136800 | D3: CASH | E3: NO | F3: 12000 nos Bricks
A4: 45927 | B4: PALANI MURUGAN | C4: 37200 | D4: CASH | E4: YES | F4: Cement Payment
A5: 45927 | B5: AK STEELS | C5: 80650 | D5: CASH | E5: YES | F5: Steel Payment
A6: 45941 | B6: PALANI MURUGAN | C6: 29500 | D6: ACC | E6: YES | F6: Cement Payment
A7: 45947 | B7: RSK | C7: 100000 | D7: CASH | E7: NO | F7: Part Payment
A8: 45955 | B8: PALANI MURUGAN | C8: 17700 | D8: CASH | E8: YES | F8: Cement Payment
A9: 45955 | B9: AK STEELS | C9: 8350 | D9: CASH | E9: YES | F9: Steel Payment
A10: 45955 | B10: VEL BRICK | C10: 136800 | D10: CASH | E10: NO | F10: Brick Payment 12000 nos
A11: 45976 | B11: AK STEELS | C11: 16370 | D11: CASH | E11: YES | F11: Steel Part Payment
A12: 45983 | B12: AK STEELS | C12: 50000 | D12: CASH | E12: YES | F12: Roof Steel Part Payment
A13: 45983 | B13: RSK | C13: 50000 | D13: CASH | E13: NO | F13: Part Payment
... A22: 46023 | B22: RSK | C22: 50000 | D22: UPI | E22: NO | F22: Part Payment
A23: 46025 | B23: RAMDEV ELECTRICALS | C23: 17500 | E23: YES | F23: Part Payment
A24: 46032 | B24: PALANI MURUGAN | C24: 16200 | D24: CASH | E24: YES | F24: Pending Amt
A25: 46053 | B25: AK STEELS | C25: 25000 | D25: CASH | E25: YES | F25: Part Payment
A26: 46053 | B26: NV ASSOCIATES | C26: 25000 | D26: ACC | E26: YES | F26: Part Payment
A27: 46060 | B27: AK STEELS | C27: 105000 | D27: CASH | E27: YES | F27: Part Payment
A28: 46067 | B28: NV ASSOCIATES | C28: 10000 | D28: CASH | E28: YES | F28: Part Payment
A29: 46074 | B29: VEL BRICK | C29: 36000 | D29: CASH | E29: NO | F29: 3000 nos brick
A30: 46074 | B30: NV ASSOCIATES | C30: 6250 | D30: CASH | E30: YES | F30: Cement Payment
A31: 46088 | B31: RSK | C31: 50000 | D31: CASH | E31: NO | F31: Part Payment
A32: 46102 | B32: PALANI MURUGAN | C32: 10750 | D32: CASH | E32: YES | F32: Part Payment
A33: 46102 | B33: CHAKRA TRADERS | C33: 13500 | D33: CASH | E33: YES | F33: Pending Payment
A34: 46109 | B34: AK STEELS | C34: 50000 | D34: CASH | E34: YES | F34: Part Payment
A35: 46120 | B35: VEL BRICK | C35: 19200 | D35: CASH | E35: NO | F35: Cash Transferred from Echanari Site
... A47: 46179 | B47: ICONIC TRADERS | C47: 11600 | D47: CASH | E47: YES | F47: paid 11500
A48: 46179 | B48: CHAKRA TRADERS | C48: 30000 | D48: CASH | E48: YES
